Workbook

Sheet Transports
A1: To be filled | B1: servicenow token: | C1: 118c2756d3ce653d0a273be09b5db6c54e | D1: Note: This token expires every 6 months, please ensure it is not expired before using it. U: servicenow P:(syspass)
A2: Result | B2: it_qa token: | C2: 11670cc89254539b7527b5113a68e6edb6 | D2: Note: This token expires every 6 months, please ensure it is not expired before using it. U: it_qa P:(syspass) | E2: (expired, not used anymore)
A3: Calculated | C3: Published 01/05/2025 | D3: 45962
A4: Project | B4: SCR Execution Body (copy & paste in SCR Execution tab) | C4: App Token | D4: Jenkins job path | E4: WithParams? | F4: SAP ID | G4: App | H4: JENKINS_TRANSPORT | I4: JENKINS_RESULT | J4: CAB
A5: Webs | B5: =CONCATENATE($I$4," ",I5,CHAR(10),CHAR(13),CHAR(10),CHAR(13),$H$4," ",H5) -> JENKINS_RESULT https://jenkins.werfen.com/job/Werfen%20websites/job/Production%20environment/job/QA%20Transports/job/All%20werfen.com%20sites/?token=WerfenALLRelease _x000D_ _x000D_JENKINS_TRANSPORT https://jenkins.werfen.com/job/Werfen%20websites/job/Production%20environment/job/QA%20Transports/job/All%20werfen.com%20sites/build?token=WerfenALLRelease&token2= | C5: WerfenALLRelease | D5: job/Werfen%20websites/job/Production%20environment/job/QA%20Transports/job/All%20werfen.com%20sites/ | E5: build | F5: 1 | G5: All werfen sites legacy | H5: =CONCATENATE("https://jenkins.werfen.com/",D5,E5,"?token=",C5,"&token2=") -> https://jenkins.werfen.com/job/Werfen%20websites/job/Production%20environment/job/QA%20Transports/job/All%20werfen.com%20sites/build?token=WerfenALLRelease&token2= | I5: =_xlfn.CONCAT("https://jenkins.werfen.com/",D5,"?token=",C5) -> https://jenkins.werfen.com/job/Werfen%20websites/job/Production%20environment/job/QA%20Transports/job/All%20werfen.com%20sites/?token=WerfenALLRelease | J5: 0
A6: Webs | B6: =CONCATENATE($I$4," ",I6,CHAR(10),CHAR(13),CHAR(10),CHAR(13),$H$4," ",H6) -> JENKINS_RESULT https://jenkins.werfen.com/job/Werfen%20websites/job/Production%20environment/job/QA%20Transports/job/All%20werfen%20sites%20release/?token=WerfenALLRelease1 _x000D_ _x000D_JENKINS_TRANSPORT https://jenkins.werfen.com/job/Werfen%20websites/job/Production%20environment/job/QA%20Transports/job/All%20werfen%20sites%20release/build?token=WerfenALLRelease1&token2= | C6: WerfenALLRelease1 | D6: job/Werfen%20websites/job/Production%20environment/job/QA%20Transports/job/All%20werfen%20sites%20release/ | E6: build | G6: All werfen sites release | H6: =CONCATENATE("https://jenkins.werfen.com/",D6,E6,"?token=",C6,"&token2=") -> https://jenkins.werfen.com/job/Werfen%20websites/job/Production%20environment/job/QA%20Transports/job/All%20werfen%20sites%20release/build?token=WerfenALLRelease1&token2= | I6: =_xlfn.CONCAT("https://jenkins.werfen.com/",D6,"?token=",C6) -> https://jenkins.werfen.com/job/Werfen%20websites/job/Production%20environment/job/QA%20Transports/job/All%20werfen%20sites%20release/?token=WerfenALLRelease1 | J6: 1
A7: Webs | B7: =CONCATENATE($I$4," ",I7,CHAR(10),CHAR(13),CHAR(10),CHAR(13),$H$4," ",H7) -> JENKINS_RESULT https://jenkins.werfen.com/job/Werfen%20websites/job/Production%20environment/job/QA%20Transports/job/All%20werfen%20hotfix/?token=WerfenALLHotfix _x000D_ _x000D_JENKINS_TRANSPORT https://jenkins.werfen.com/job/Werfen%20websites/job/Production%20environment/job/QA%20Transports/job/All%20werfen%20hotfix/build?token=WerfenALLHotfix&token2= | C7: WerfenALLHotfix | D7: job/Werfen%20websites/job/Production%20environment/job/QA%20Transports/job/All%20werfen%20hotfix/ | E7: build | G7: All werfen sites hotfix | H7: =CONCATENATE("https://jenkins.werfen.com/",D7,E7,"?token=",C7,"&token2=") -> https://jenkins.werfen.com/job/Werfen%20websites/job/Production%20environment/job/QA%20Transports/job/All%20werfen%20hotfix/build?token=WerfenALLHotfix&token2= | I7: =_xlfn.CONCAT("https://jenkins.werfen.com/",D7,"?token=",C7) -> https://jenkins.werfen.com/job/Werfen%20websites/job/Production%20environment/job/QA%20Transports/job/All%20werfen%20hotfix/?token=WerfenALLHotfix | J7: 1
A8: Webs | B8: =CONCATENATE($I$4," ",I8,CHAR(10),CHAR(13),CHAR(10),CHAR(13),$H$4," ",H8) -> JENKINS_RESULT https://jenkins.werfen.com/job/Werfen%20websites/job/Production%20environment/job/QA%20Transports/job/Werfen%20CZ/?token=WerfenCZRelease _x000D_ _x000D_JENKINS_TRANSPORT https://jenkins.werfen.com/job/Werfen%20websites/job/Production%20environment/job/QA%20Transports/job/Werfen%20CZ/buildWithParameters?token=WerfenCZRelease&token2= | C8: WerfenCZRelease | D8: job/Werfen%20websites/job/Production%20environment/job/QA%20Transports/job/Werfen%20CZ/ | E8: buildWithParameters | F8: 8 | G8: Website Czechia legacy | H8: =CONCATENATE("https://jenkins.werfen.com/",D8,E8,"?token=",C8,"&token2=") -> https://jenkins.werfen.com/job/Werfen%20websites/job/Production%20environment/job/QA%20Transports/job/Werfen%20CZ/buildWithParameters?token=WerfenCZRelease&token2= | I8: =_xlfn.CONCAT("https://jenkins.werfen.com/",D8,"?token=",C8) -> https://jenkins.werfen.com/job/Werfen%20websites/job/Production%20environment/job/QA%20Transports/job/Werfen%20CZ/?token=WerfenCZRelease | J8: 0
A9: Webs | B9: =CONCATENATE($I$4," ",I9,CHAR(10),CHAR(13),CHAR(10),CHAR(13),$H$4," ",H9) -> JENKINS_RESULT https://jenkins.werfen.com/job/Werfen%20websites/job/Production%20environment/job/QA%20Transports/job/Werfen%20CZ%20release/?token=WerfenCZRelease1 _x000D_ _x000D_JENKINS_TRANSPORT https://jenkins.werfen.com/job/Werfen%20websites/job/Production%20environment/job/QA%20Transports/job/Werfen%20CZ%20release/buildWithParameters?token=WerfenCZRelease1&token2= | C9: WerfenCZRelease1 | D9: job/Werfen%20websites/job/Production%20environment/job/QA%20Transports/job/Werfen%20CZ%20release/ | E9: buildWithParameters | G9: Website Czechia release | H9: =CONCATENATE("https://jenkins.werfen.com/",D9,E9,"?token=",C9,"&token2=") -> https://jenkins.werfen.com/job/Werfen%20websites/job/Production%20environment/job/QA%20Transports/job/Werfen%20CZ%20release/buildWithParameters?token=WerfenCZRelease1&token2= | I9: =_xlfn.CONCAT("https://jenkins.werfen.com/",D9,"?token=",C9) -> https://jenkins.werfen.com/job/Werfen%20websites/job/Production%20environment/job/QA%20Transports/job/Werfen%20CZ%20release/?token=WerfenCZRelease1 | J9: 1
A10: Webs | B10: =CONCATENATE($I$4," ",I10,CHAR(10),CHAR(13),CHAR(10),CHAR(13),$H$4," ",H10) -> JENKINS_RESULT https://jenkins.werfen.com/job/Werfen%20websites/job/Production%20environment/job/QA%20Transports/job/Werfen%20CZ%20hotfix/?token=WerfenCZHotfix _x000D_ _x000D_JENKINS_TRANSPORT https://jenkins.werfen.com/job/Werfen%20websites/job/Production%20environment/job/QA%20Transports/job/Werfen%20CZ%20hotfix/buildWithParameters?token=WerfenCZHotfix&token2= | C10: WerfenCZHotfix | D10: job/Werfen%20websites/job/Production%20environment/job/QA%20Transports/job/Werfen%20CZ%20hotfix/ | E10: buildWithParameters | G10: Website Czechia hotfix | H10: =CONCATENATE("https://jenkins.werfen.com/",D10,E10,"?token=",C10,"&token2=") -> https://jenkins.werfen.com/job/Werfen%20websites/job/Production%20environment/job/QA%20Transports/job/Werfen%20CZ%20hotfix/buildWithParameters?token=WerfenCZHotfix&token2= | I10: =_xlfn.CONCAT("https://jenkins.werfen.com/",D10,"?token=",C10) -> https://jenkins.werfen.com/job/Werfen%20websites/job/Production%20environment/job/QA%20Transports/job/Werfen%20CZ%20hotfix/?token=WerfenCZHotfix | J10: 1
A11: Webs | B11: =CONCATENATE($I$4," ",I11,CHAR(10),CHAR(13),CHAR(10),CHAR(13),$H$4," ",H11) -> JENKINS_RESULT https://jenkins.werfen.com/job/Werfen%20websites/job/Production%20environment/job/QA%20Transports/job/Werfen%20RU/?token=WerfenRURelease _x000D_ _x000D_JENKINS_TRANSPORT https://jenkins.werfen.com/job/Werfen%20websites/job/Production%20environment/job/QA%20Transports/job/Werfen%20RU/buildWithParameters?token=WerfenRURelease&token2= | C11: WerfenRURelease | D11: job/Werfen%20websites/job/Production%20environment/job/QA%20Transports/job/Werfen%20RU/ | E11: buildWithParameters | F11: 22 | G11: Website Russia legacy | H11: =CONCATENATE("https://jenkins.werfen.com/",D11,E11,"?token=",C11,"&token2=") -> https://jenkins.werfen.com/job/Werfen%20websites/job/Production%20environment/job/QA%20Transports/job/Werfen%20RU/buildWithParameters?token=WerfenRURelease&token2= | I11: =_xlfn.CONCAT("https://jenkins.werfen.com/",D11,"?token=",C11) -> https://jenkins.werfen.com/job/Werfen%20websites/job/Production%20environment/job/QA%20Transports/job/Werfen%20RU/?token=WerfenRURelease | J11: 0
A12: Webs | B12: =CONCATENATE($I$4," ",I12,CHAR(10),CHAR(13),CHAR(10),CHAR(13),$H$4," ",H12) -> JENKINS_RESULT https://jenkins.werfen.com/job/Werfen%20websites/job/Production%20environment/job/QA%20Transports/job/Werfen%20RU%20release/?token=WerfenRURelease1 _x000D_ _x000D_JENKINS_TRANSPORT https://jenkins.werfen.com/job/Werfen%20websites/job/Production%20environment/job/QA%20Transports/job/Werfen%20RU%20release/buildWithParameters?token=WerfenRURelease1&token2= | C12: WerfenRURelease1 | D12: job/Werfen%20websites/job/Production%20environment/job/QA%20Transports/job/Werfen%20RU%20release/ | E12: buildWithParameters | G12: Website Russia release | H12: =CONCATENATE("https://jenkins.werfen.com/",D12,E12,"?token=",C12,"&token2=") -> https://jenkins.werfen.com/job/Werfen%20websites/job/Production%20environment/job/QA%20Transports/job/Werfen%20RU%20release/buildWithParameters?token=WerfenRURelease1&token2= | I12: =_xlfn.CONCAT("https://jenkins.werfen.com/",D12,"?token=",C12) -> https://jenkins.werfen.com/job/Werfen%20websites/job/Production%20environment/job/QA%20Transports/job/Werfen%20RU%20release/?token=WerfenRURelease1 | J12: 1
A13: Webs | B13: =CONCATENATE($I$4," ",I13,CHAR(10),CHAR(13),CHAR(10),CHAR(13),$H$4," ",H13) -> JENKINS_RESULT https://jenkins.werfen.com/job/Werfen%20websites/job/Production%20environment/job/QA%20Transports/job/Werfen%20RU%20hotfix/?token=WerfenRUHotfix _x000D_ _x000D_JENKINS_TRANSPORT https://jenkins.werfen.com/job/Werfen%20websites/job/Production%20environment/job/QA%20Transports/job/Werfen%20RU%20hotfix/?token=WerfenRUHotfix&token2= | C13: WerfenRUHotfix | D13: job/Werfen%20websites/job/Production%20environment/job/QA%20Transports/job/Werfen%20RU%20hotfix/ | F13: 22 | G13: Website Russia hotfix | H13: =CONCATENATE("https://jenkins.werfen.com/",D13,E13,"?token=",C13,"&token2=") -> https://jenkins.werfen.com/job/Werfen%20websites/job/Production%20environment/job/QA%20Transports/job/Werfen%20RU%20hotfix/?token=WerfenRUHotfix&token2= | I13: =_xlfn.CONCAT("https://jenkins.werfen.com/",D13,"?token=",C13) -> https://jenkins.werfen.com/job/Werfen%20websites/job/Production%20environment/job/QA%20Transports/job/Werfen%20RU%20hotfix/?token=WerfenRUHotfix | J13: 1
A14: Webs | B14: =CONCATENATE($I$4," ",I14,CHAR(10),CHAR(13),CHAR(10),CHAR(13),$H$4," ",H14) -> JENKINS_RESULT https://jenkins.werfen.com/job/Werfen%20websites/job/Production%20environment/job/QA%20Transports/job/Werfen%20AU/?token=WerfenAURelease _x000D_ _x000D_JENKINS_TRANSPORT https://jenkins.werfen.com/job/Werfen%20websites/job/Production%20environment/job/QA%20Transports/job/Werfen%20AU/buildWithParameters?token=WerfenAURelease&token2= | C14: WerfenAURelease | D14: job/Werfen%20websites/job/Production%20environment/job/QA%20Transports/job/Werfen%20AU/ | E14: buildWithParameters | F14: 4 | G14: Website AUSTRALIA legacy | H14: =CONCATENATE("https://jenkins.werfen.com/",D14,E14,"?token=",C14,"&token2=") -> https://jenkins.werfen.com/job/Werfen%20websites/job/Production%20environment/job/QA%20Transports/job/Werfen%20AU/buildWithParameters?token=WerfenAURelease&token2= | I14: =_xlfn.CONCAT("https://jenkins.werfen.com/",D14,"?token=",C14) -> https://jenkins.werfen.com/job/Werfen%20websites/job/Production%20environment/job/QA%20Transports/job/Werfen%20AU/?token=WerfenAURelease | J14: 0
A15: Webs | B15: =CONCATENATE($I$4," ",I15,CHAR(10),CHAR(13),CHAR(10),CHAR(13),$H$4," ",H15) -> JENKINS_RESULT https://jenkins.werfen.com/job/Werfen%20websites/job/Production%20environment/job/QA%20Transports/job/Werfen%20AU%20release/?token=WerfenAURelease1 _x000D_ _x000D_JENKINS_TRANSPORT https://jenkins.werfen.com/job/Werfen%20websites/job/Production%20environment/job/QA%20Transports/job/Werfen%20AU%20release/buildWithParameters?token=WerfenAURelease1&token2= | C15: WerfenAURelease1 | D15: job/Werfen%20websites/job/Production%20environment/job/QA%20Transports/job/Werfen%20AU%20release/ | E15: buildWithParameters | F15: 4 | G15: Website AUSTRALIA release | H15: =CONCATENATE("https://jenkins.werfen.com/",D15,E15,"?token=",C15,"&token2=") -> https://jenkins.werfen.com/job/Werfen%20websites/job/Production%20environment/job/QA%20Transports/job/Werfen%20AU%20release/buildWithParameters?token=WerfenAURelease1&token2= | I15: =_xlfn.CONCAT("https://jenkins.werfen.com/",D15,"?token=",C15) -> https://jenkins.werfen.com/job/Werfen%20websites/job/Production%20environment/job/QA%20Transports/job/Werfen%20AU%20release/?token=WerfenAURelease1 | J15: 1
A16: Webs | B16: =CONCATENATE($I$4," ",I16,CHAR(10),CHAR(13),CHAR(10),CHAR(13),$H$4," ",H16) -> JENKINS_RESULT https://jenkins.werfen.com/job/Werfen%20websites/job/Production%20environment/job/QA%20Transports/job/Werfen%20AU%20hotfix/?token=WerfenAUHotfix _x000D_ _x000D_JENKINS_TRANSPORT https://jenkins.werfen.com/job/Werfen%20websites/job/Production%20environment/job/QA%20Transports/job/Werfen%20AU%20hotfix/buildWithParameters?token=WerfenAUHotfix&token2= | C16: WerfenAUHotfix | D16: job/Werfen%20websites/job/Production%20environment/job/QA%20Transports/job/Werfen%20AU%20hotfix/ | E16: buildWithParameters | F16: 4 | G16: Website AUSTRALIA hotfix | H16: =CONCATENATE("https://jenkins.werfen.com/",D16,E16,"?token=",C16,"&token2=") -> https://jenkins.werfen.com/job/Werfen%20websites/job/Production%20environment/job/QA%20Transports/job/Werfen%20AU%20hotfix/buildWithParameters?token=WerfenAUHotfix&token2= | I16: =_xlfn.CONCAT("https://jenkins.werfen.com/",D16,"?token=",C16) -> https://jenkins.werfen.com/job/Werfen%20websites/job/Production%20environment/job/QA%20Transports/job/Werfen%20AU%20hotfix/?token=WerfenAUHotfix | J16: 1
A17: Welisten | B17: =CONCATENATE($I$4," ",I17,CHAR(10),CHAR(13),CHAR(10),CHAR(13),$H$4," ",H17) -> JENKINS_RESULT https://jenkins.werfen.com/job/WeListen/job/Production%20environment/job/QA%20Transports/job/Deploy%20site/?token=welistenRelease _x000D_ _x000D_JENKINS_TRANSPORT https://jenkins.werfen.com/job/WeListen/job/Production%20environment/job/QA%20Transports/job/Deploy%20site/buildWithParameters?token=welistenRelease&token2= | C17: welistenRelease | D17: job/WeListen/job/Production%20environment/job/QA%20Transports/job/Deploy%20site/ | E17: buildWithParameters | F17: 28 | G17: WeListen legacy | H17: =CONCATENATE("https://jenkins.werfen.com/",D17,E17,"?token=",C17,"&token2=") -> https://jenkins.werfen.com/job/WeListen/job/Production%20environment/job/QA%20Transports/job/Deploy%20site/buildWithParameters?token=welistenRelease&token2= | I17: =_xlfn.CONCAT("https://jenkins.werfen.com/",D17,"?token=",C17) -> https://jenkins.werfen.com/job/WeListen/job/Production%20environment/job/QA%20Transports/job/Deploy%20site/?token=welistenRelease | J17: 0
A18: Welisten | B18: =CONCATENATE($I$4," ",I18,CHAR(10),CHAR(13),CHAR(10),CHAR(13),$H$4," ",H18) -> JENKINS_RESULT https://jenkins.werfen.com/job/WeListen/job/Production%20environment/job/QA%20Transports/job/Deploy%20release/?token=welistenRelease1 _x000D_ _x000D_JENKINS_TRANSPORT https://jenkins.werfen.com/job/WeListen/job/Production%20environment/job/QA%20Transports/job/Deploy%20release/buildWithParameters?token=welistenRelease1&token2= | C18: welistenRelease1 | D18: job/WeListen/job/Production%20environment/job/QA%20Transports/job/Deploy%20release/ | E18: buildWithParameters | G18: WeListen release | H18: =CONCATENATE("https://jenkins.werfen.com/",D18,E18,"?token=",C18,"&token2=") -> https://jenkins.werfen.com/job/WeListen/job/Production%20environment/job/QA%20Transports/job/Deploy%20release/buildWithParameters?token=welistenRelease1&token2= | I18: =_xlfn.CONCAT("https://jenkins.werfen.com/",D18,"?token=",C18) -> https://jenkins.werfen.com/job/WeListen/job/Production%20environment/job/QA%20Transports/job/Deploy%20release/?token=welistenRelease1 | J18: 1
A19: Welisten | B19: =CONCATENATE($I$4," ",I19,CHAR(10),CHAR(13),CHAR(10),CHAR(13),$H$4," ",H19) -> JENKINS_RESULT https://jenkins.werfen.com/job/WeListen/job/Production%20environment/job/QA%20Transports/job/Deploy%20hotfix/?token=welistenHotfix _x000D_ _x000D_JENKINS_TRANSPORT https://jenkins.werfen.com/job/WeListen/job/Production%20environment/job/QA%20Transports/job/Deploy%20hotfix/buildWithParameters?token=welistenHotfix&token2= | C19: welistenHotfix | D19: job/WeListen/job/Production%20environment/job/QA%20Transports/job/Deploy%20hotfix/ | E19: buildWithParameters | G19: WeListen hotfix | H19: =CONCATENATE("https://jenkins.werfen.com/",D19,E19,"?token=",C19,"&token2=") -> https://jenkins.werfen.com/job/WeListen/job/Production%20environment/job/QA%20Transports/job/Deploy%20hotfix/buildWithParameters?token=welistenHotfix&token2= | I19: =_xlfn.CONCAT("https://jenkins.werfen.com/",D19,"?token=",C19) -> https://jenkins.werfen.com/job/WeListen/job/Production%20environment/job/QA%20Transports/job/Deploy%20hotfix/?token=welistenHotfix | J19: 1
A20: Webs | B20: =CONCATENATE($I$4," ",I20,CHAR(10),CHAR(13),CHAR(10),CHAR(13),$H$4," ",H20) -> JENKINS_RESULT https://jenkins.werfen.com/job/Werfen%20websites/job/Production%20environment/job/QA%20Transports/job/Werfen%20FR/?token=WerfenFRRelease _x000D_ _x000D_JENKINS_TRANSPORT https://jenkins.werfen.com/job/Werfen%20websites/job/Production%20environment/job/QA%20Transports/job/Werfen%20FR/buildWithParameters?token=WerfenFRRelease&token2= | C20: WerfenFRRelease | D20: job/Werfen%20websites/job/Production%20environment/job/QA%20Transports/job/Werfen%20FR/ | E20: buildWithParameters | F20: 9 | G20: Website FRANCE legacy | H20: =CONCATENATE("https://jenkins.werfen.com/",D20,E20,"?token=",C20,"&token2=") -> https://jenkins.werfen.com/job/Werfen%20websites/job/Production%20environment/job/QA%20Transports/job/Werfen%20FR/buildWithParameters?token=WerfenFRRelease&token2= | I20: =_xlfn.CONCAT("https://jenkins.werfen.com/",D20,"?token=",C20) -> https://jenkins.werfen.com/job/Werfen%20websites/job/Production%20environment/job/QA%20Transports/job/Werfen%20FR/?token=WerfenFRRelease | J20: 0
A21: Webs | B21: =CONCATENATE($I$4," ",I21,CHAR(10),CHAR(13),CHAR(10),CHAR(13),$H$4," ",H21) -> JENKINS_RESULT https://jenkins.werfen.com/job/Werfen%20websites/job/Production%20environment/job/QA%20Transports/job/Werfen%20FR%20release/?token=WerfenFRRelease1 _x000D_ _x000D_JENKINS_TRANSPORT https://jenkins.werfen.com/job/Werfen%20websites/job/Production%20environment/job/QA%20Transports/job/Werfen%20FR%20release/buildWithParameters?token=WerfenFRRelease1&token2= | C21: WerfenFRRelease1 | D21: job/Werfen%20websites/job/Production%20environment/job/QA%20Transports/job/Werfen%20FR%20release/ | E21: buildWithParameters | G21: Website FRANCE release | H21: =CONCATENATE("https://jenkins.werfen.com/",D21,E21,"?token=",C21,"&token2=") -> https://jenkins.werfen.com/job/Werfen%20websites/job/Production%20environment/job/QA%20Transports/job/Werfen%20FR%20release/buildWithParameters?token=WerfenFRRelease1&token2= | I21: =_xlfn.CONCAT("https://jenkins.werfen.com/",D21,"?token=",C21) -> https://jenkins.werfen.com/job/Werfen%20websites/job/Production%20environment/job/QA%20Transports/job/Werfen%20FR%20release/?token=WerfenFRRelease1 | J21: 1
A22: Webs | B22: =CONCATENATE($I$4," ",I22,CHAR(10),CHAR(13),CHAR(10),CHAR(13),$H$4," ",H22) -> JENKINS_RESULT https://jenkins.werfen.com/job/Werfen%20websites/job/Production%20environment/job/QA%20Transports/job/Werfen%20FR%20hotifx/?token=WerfenFRHotfix _x000D_ _x000D_JENKINS_TRANSPORT https://jenkins.werfen.com/job/Werfen%20websites/job/Production%20environment/job/QA%20Transports/job/Werfen%20FR%20hotifx/buildWithParameters?token=WerfenFRHotfix&token2= | C22: WerfenFRHotfix | D22: job/Werfen%20websites/job/Production%20environment/job/QA%20Transports/job/Werfen%20FR%20hotifx/ | E22: buildWithParameters | G22: Website FRANCE hotfix | H22: =CONCATENATE("https://jenkins.werfen.com/",D22,E22,"?token=",C22,"&token2=") -> https://jenkins.werfen.com/job/Werfen%20websites/job/Production%20environment/job/QA%20Transports/job/Werfen%20FR%20hotifx/buildWithParameters?token=WerfenFRHotfix&token2= | I22: =_xlfn.CONCAT("https://jenkins.werfen.com/",D22,"?token=",C22) -> https://jenkins.werfen.com/job/Werfen%20websites/job/Production%20environment/job/QA%20Transports/job/Werfen%20FR%20hotifx/?token=WerfenFRHotfix | J22: 1
A23: Webs | B23: =CONCATENATE($I$4," ",I23,CHAR(10),CHAR(13),CHAR(10),CHAR(13),$H$4," ",H23) -> JENKINS_RESULT https://jenkins.werfen.com/job/Werfen%20websites/job/Production%20environment/job/QA%20Transports/job/Werfen%20IT/?token=WerfenITRelease _x000D_ _x000D_JENKINS_TRANSPORT https://jenkins.werfen.com/job/Werfen%20websites/job/Production%20environment/job/QA%20Transports/job/Werfen%20IT/buildWithParameters?token=WerfenITRelease&token2= | C23: WerfenITRelease | D23: job/Werfen%20websites/job/Production%20environment/job/QA%20Transports/job/Werfen%20IT/ | E23: buildWithParameters | F23: 11 | G23: Website Italy legacy | H23: =CONCATENATE("https://jenkins.werfen.com/",D23,E23,"?token=",C23,"&token2=") -> https://jenkins.werfen.com/job/Werfen%20websites/job/Production%20environment/job/QA%20Transports/job/Werfen%20IT/buildWithParameters?token=WerfenITRelease&token2= | I23: =_xlfn.CONCAT("https://jenkins.werfen.com/",D23,"?token=",C23) -> https://jenkins.werfen.com/job/Werfen%20websites/job/Production%20environment/job/QA%20Transports/job/Werfen%20IT/?token=WerfenITRelease | J23: 0
A24: Webs | B24: =CONCATENATE($I$4," ",I24,CHAR(10),CHAR(13),CHAR(10),CHAR(13),$H$4," ",H24) -> JENKINS_RESULT https://jenkins.werfen.com/job/Werfen%20websites/job/Production%20environment/job/QA%20Transports/job/Werfen%20IT%20release/?token=WerfenITRelease1 _x000D_ _x000D_JENKINS_TRANSPORT https://jenkins.werfen.com/job/Werfen%20websites/job/Production%20environment/job/QA%20Transports/job/Werfen%20IT%20release/buildWithParameters?token=WerfenITRelease1&token2= | C24: WerfenITRelease1 | D24: job/Werfen%20websites/job/Production%20environment/job/QA%20Transports/job/Werfen%20IT%20release/ | E24: buildWithParameters | G24: Website Italy release | H24: =CONCATENATE("https://jenkins.werfen.com/",D24,E24,"?token=",C24,"&token2=") -> https://jenkins.werfen.com/job/Werfen%20websites/job/Production%20environment/job/QA%20Transports/job/Werfen%20IT%20release/buildWithParameters?token=WerfenITRelease1&token2= | I24: =_xlfn.CONCAT("https://jenkins.werfen.com/",D24,"?token=",C24) -> https://jenkins.werfen.com/job/Werfen%20websites/job/Production%20environment/job/QA%20Transports/job/Werfen%20IT%20release/?token=WerfenITRelease1 | J24: 1
A25: Webs | B25: =CONCATENATE($I$4," ",I25,CHAR(10),CHAR(13),CHAR(10),CHAR(13),$H$4," ",H25) -> JENKINS_RESULT https://jenkins.werfen.com/job/Werfen%20websites/job/Production%20environment/job/QA%20Transports/job/Werfen%20IT%20hotfix/?token=WerfenITHotfix _x000D_ _x000D_JENKINS_TRANSPORT https://jenkins.werfen.com/job/Werfen%20websites/job/Production%20environment/job/QA%20Transports/job/Werfen%20IT%20hotfix/buildWithParameters?token=WerfenITHotfix&token2= | C25: WerfenITHotfix | D25: job/Werfen%20websites/job/Production%20environment/job/QA%20Transports/job/Werfen%20IT%20hotfix/ | E25: buildWithParameters | G25: Website Italy hotfix | H25: =CONCATENATE("https://jenkins.werfen.com/",D25,E25,"?token=",C25,"&token2=") -> https://jenkins.werfen.com/job/Werfen%20websites/job/Production%20environment/job/QA%20Transports/job/Werfen%20IT%20hotfix/buildWithParameters?token=WerfenITHotfix&token2= | I25: =_xlfn.CONCAT("https://jenkins.werfen.com/",D25,"?token=",C25) -> https://jenkins.werfen.com/job/Werfen%20websites/job/Production%20environment/job/QA%20Transports/job/Werfen%20IT%20hotfix/?token=WerfenITHotfix | J25: 1
A26: Webs | B26: =CONCATENATE($I$4," ",I26,CHAR(10),CHAR(13),CHAR(10),CHAR(13),$H$4," ",H26) -> JENKINS_RESULT https://jenkins.werfen.com/job/Werfen%20websites/job/Production%20environment/job/QA%20Transports/job/Werfen%20UK/?token=WerfenUKRelease _x000D_ _x000D_JENKINS_TRANSPORT https://jenkins.werfen.com/job/Werfen%20websites/job/Production%20environment/job/QA%20Transports/job/Werfen%20UK/buildWithParameters?token=WerfenUKRelease&token2= | C26: WerfenUKRelease | D26: job/Werfen%20websites/job/Production%20environment/job/QA%20Transports/job/Werfen%20UK/ | E26: buildWithParameters | F26: 24 | G26: Website UK legacy | H26: =CONCATENATE("https://jenkins.werfen.com/",D26,E26,"?token=",C26,"&token2=") -> https://jenkins.werfen.com/job/Werfen%20websites/job/Production%20environment/job/QA%20Transports/job/Werfen%20UK/buildWithParameters?token=WerfenUKRelease&token2= | I26: =_xlfn.CONCAT("https://jenkins.werfen.com/",D26,"?token=",C26) -> https://jenkins.werfen.com/job/Werfen%20websites/job/Production%20environment/job/QA%20Transports/job/Werfen%20UK/?token=WerfenUKRelease | J26: 0
A27: Webs | B27: =CONCATENATE($I$4," ",I27,CHAR(10),CHAR(13),CHAR(10),CHAR(13),$H$4," ",H27) -> JENKINS_RESULT https://jenkins.werfen.com/job/Werfen%20websites/job/Production%20environment/job/QA%20Transports/job/Werfen%20UK%20release/?token=WerfenUKRelease1 _x000D_ _x000D_JENKINS_TRANSPORT https://jenkins.werfen.com/job/Werfen%20websites/job/Production%20environment/job/QA%20Transports/job/Werfen%20UK%20release/buildWithParameters?token=WerfenUKRelease1&token2= | C27: WerfenUKRelease1 | D27: job/Werfen%20websites/job/Production%20environment/job/QA%20Transports/job/Werfen%20UK%20release/ | E27: buildWithParameters | G27: Website UK release | H27: =CONCATENATE("https://jenkins.werfen.com/",D27,E27,"?token=",C27,"&token2=") -> https://jenkins.werfen.com/job/Werfen%20websites/job/Production%20environment/job/QA%20Transports/job/Werfen%20UK%20release/buildWithParameters?token=WerfenUKRelease1&token2= | I27: =_xlfn.CONCAT("https://jenkins.werfen.com/",D27,"?token=",C27) -> https://jenkins.werfen.com/job/Werfen%20websites/job/Production%20environment/job/QA%20Transports/job/Werfen%20UK%20release/?token=WerfenUKRelease1 | J27: 1
A28: Webs | B28: =CONCATENATE($I$4," ",I28,CHAR(10),CHAR(13),CHAR(10),CHAR(13),$H$4," ",H28) -> JENKINS_RESULT https://jenkins.werfen.com/job/Werfen%20websites/job/Production%20environment/job/QA%20Transports/job/Werfen%20UK%20hotfix/?token=WerfenUKHotfix _x000D_ _x000D_JENKINS_TRANSPORT https://jenkins.werfen.com/job/Werfen%20websites/job/Production%20environment/job/QA%20Transports/job/Werfen%20UK%20hotfix/buildWithParameters?token=WerfenUKHotfix&token2= | C28: WerfenUKHotfix | D28: job/Werfen%20websites/job/Production%20environment/job/QA%20Transports/job/Werfen%20UK%20hotfix/ | E28: buildWithParameters | G28: Website UK hotfix | H28: =CONCATENATE("https://jenkins.werfen.com/",D28,E28,"?token=",C28,"&token2=") -> https://jenkins.werfen.com/job/Werfen%20websites/job/Production%20environment/job/QA%20Transports/job/Werfen%20UK%20hotfix/buildWithParameters?token=WerfenUKHotfix&token2= | I28: =_xlfn.CONCAT("https://jenkins.werfen.com/",D28,"?token=",C28) -> https://jenkins.werfen.com/job/Werfen%20websites/job/Production%20environment/job/QA%20Transports/job/Werfen%20UK%20hotfix/?token=WerfenUKHotfix | J28: 1
A29: Webs | B29: =CONCATENATE($I$4," ",I29,CHAR(10),CHAR(13),CHAR(10),CHAR(13),$H$4," ",H29) -> JENKINS_RESULT https://jenkins.werfen.com/job/Werfen%20websites/job/Production%20environment/job/QA%20Transports/job/Werfen%20WW/?token=WerfenWWRelease _x000D_ _x000D_JENKINS_TRANSPORT https://jenkins.werfen.com/job/Werfen%20websites/job/Production%20environment/job/QA%20Transports/job/Werfen%20WW/buildWithParameters?token=WerfenWWRelease&token2= | C29: WerfenWWRelease | D29: job/Werfen%20websites/job/Production%20environment/job/QA%20Transports/job/Werfen%20WW/ | E29: buildWithParameters | F29: 2 | G29: Website Corporate legacy | H29: =CONCATENATE("https://jenkins.werfen.com/",D29,E29,"?token=",C29,"&token2=") -> https://jenkins.werfen.com/job/Werfen%20websites/job/Production%20environment/job/QA%20Transports/job/Werfen%20WW/buildWithParameters?token=WerfenWWRelease&token2= | I29: =_xlfn.CONCAT("https://jenkins.werfen.com/",D29,"?token=",C29) -> https://jenkins.werfen.com/job/Werfen%20websites/job/Production%20environment/job/QA%20Transports/job/Werfen%20WW/?token=WerfenWWRelease | J29: 0
A30: Webs | B30: =CONCATENATE($I$4," ",I30,CHAR(10),CHAR(13),CHAR(10),CHAR(13),$H$4," ",H30) -> JENKINS_RESULT https://jenkins.werfen.com/job/Werfen%20websites/job/Production%20environment/job/QA%20Transports/job/Werfen%20WW%20release/?token=WerfenWWRelease1 _x000D_ _x000D_JENKINS_TRANSPORT https://jenkins.werfen.com/job/Werfen%20websites/job/Production%20environment/job/QA%20Transports/job/Werfen%20WW%20release/buildWithParameters?token=WerfenWWRelease1&token2= | C30: WerfenWWRelease1 | D30: job/Werfen%20websites/job/Production%20environment/job/QA%20Transports/job/Werfen%20WW%20release/ | E30: buildWithParameters | G30: Website Corporate release | H30: =CONCATENATE("https://jenkins.werfen.com/",D30,E30,"?token=",C30,"&token2=") -> https://jenkins.werfen.com/job/Werfen%20websites/job/Production%20environment/job/QA%20Transports/job/Werfen%20WW%20release/buildWithParameters?token=WerfenWWRelease1&token2= | I30: =_xlfn.CONCAT("https://jenkins.werfen.com/",D30,"?token=",C30) -> https://jenkins.werfen.com/job/Werfen%20websites/job/Production%20environment/job/QA%20Transports/job/Werfen%20WW%20release/?token=WerfenWWRelease1 | J30: 1
A31: Webs | B31: =CONCATENATE($I$4," ",I31,CHAR(10),CHAR(13),CHAR(10),CHAR(13),$H$4," ",H31) -> JENKINS_RESULT https://jenkins.werfen.com/job/Werfen%20websites/job/Production%20environment/job/QA%20Transports/job/Werfen%20WW%20hotfix/?token=WerfenWWHotfix _x000D_ _x000D_JENKINS_TRANSPORT https://jenkins.werfen.com/job/Werfen%20websites/job/Production%20environment/job/QA%20Transports/job/Werfen%20WW%20hotfix/buildWithParameters?token=WerfenWWHotfix&token2= | C31: WerfenWWHotfix | D31: job/Werfen%20websites/job/Production%20environment/job/QA%20Transports/job/Werfen%20WW%20hotfix/ | E31: buildWithParameters | G31: Website Corporate hotfix | H31: =CONCATENATE("https://jenkins.werfen.com/",D31,E31,"?token=",C31,"&token2=") -> https://jenkins.werfen.com/job/Werfen%20websites/job/Production%20environment/job/QA%20Transports/job/Werfen%20WW%20hotfix/buildWithParameters?token=WerfenWWHotfix&token2= | I31: =_xlfn.CONCAT("https://jenkins.werfen.com/",D31,"?token=",C31) -> https://jenkins.werfen.com/job/Werfen%20websites/job/Production%20environment/job/QA%20Transports/job/Werfen%20WW%20hotfix/?token=WerfenWWHotfix | J31: 1
A32: Webs | B32: =CONCATENATE($I$4," ",I32,CHAR(10),CHAR(13),CHAR(10),CHAR(13),$H$4," ",H32) -> JENKINS_RESULT https://jenkins.werfen.com/job/Werfen%20websites/job/Production%20environment/job/QA%20Transports/job/Werfen%20MX/?token=WerfenMXRelease _x000D_ _x000D_JENKINS_TRANSPORT https://jenkins.werfen.com/job/Werfen%20websites/job/Production%20environment/job/QA%20Transports/job/Werfen%20MX/buildWithParameters?token=WerfenMXRelease&token2= | C32: WerfenMXRelease | D32: job/Werfen%20websites/job/Production%20environment/job/QA%20Transports/job/Werfen%20MX/ | E32: buildWithParameters | F32: 18 | G32: Website Mexico legacy | H32: =CONCATENATE("https://jenkins.werfen.com/",D32,E32,"?token=",C32,"&token2=") -> https://jenkins.werfen.com/job/Werfen%20websites/job/Production%20environment/job/QA%20Transports/job/Werfen%20MX/buildWithParameters?token=WerfenMXRelease&token2= | I32: =_xlfn.CONCAT("https://jenkins.werfen.com/",D32,"?token=",C32) -> https://jenkins.werfen.com/job/Werfen%20websites/job/Production%20environment/job/QA%20Transports/job/Werfen%20MX/?token=WerfenMXRelease | J32: 0
A33: Webs | B33: =CONCATENATE($I$4," ",I33,CHAR(10),CHAR(13),CHAR(10),CHAR(13),$H$4," ",H33) -> JENKINS_RESULT https://jenkins.werfen.com/job/Werfen%20websites/job/Production%20environment/job/QA%20Transports/job/Werfen%20MX%20release/?token=WerfenMXRelease1 _x000D_ _x000D_JENKINS_TRANSPORT https://jenkins.werfen.com/job/Werfen%20websites/job/Production%20environment/job/QA%20Transports/job/Werfen%20MX%20release/buildWithParameters?token=WerfenMXRelease1&token2= | C33: WerfenMXRelease1 | D33: job/Werfen%20websites/job/Production%20environment/job/QA%20Transports/job/Werfen%20MX%20release/ | E33: buildWithParameters | G33: Website Mexico release | H33: =CONCATENATE("https://jenkins.werfen.com/",D33,E33,"?token=",C33,"&token2=") -> https://jenkins.werfen.com/job/Werfen%20websites/job/Production%20environment/job/QA%20Transports/job/Werfen%20MX%20release/buildWithParameters?token=WerfenMXRelease1&token2= | I33: =_xlfn.CONCAT("https://jenkins.werfen.com/",D33,"?token=",C33) -> https://jenkins.werfen.com/job/Werfen%20websites/job/Production%20environment/job/QA%20Transports/job/Werfen%20MX%20release/?token=WerfenMXRelease1 | J33: 1
A34: Webs | B34: =CONCATENATE($I$4," ",I34,CHAR(10),CHAR(13),CHAR(10),CHAR(13),$H$4," ",H34) -> JENKINS_RESULT https://jenkins.werfen.com/job/Werfen%20websites/job/Production%20environment/job/QA%20Transports/job/Werfen%20MX%20hotfix/?token=WerfenMXHotfix _x000D_ _x000D_JENKINS_TRANSPORT https://jenkins.werfen.com/job/Werfen%20websites/job/Production%20environment/job/QA%20Transports/job/Werfen%20MX%20hotfix/buildWithParameters?token=WerfenMXHotfix&token2= | C34: WerfenMXHotfix | D34: job/Werfen%20websites/job/Production%20environment/job/QA%20Transports/job/Werfen%20MX%20hotfix/ | E34: buildWithParameters | G34: Website Mexico hotfix | H34: =CONCATENATE("https://jenkins.werfen.com/",D34,E34,"?token=",C34,"&token2=") -> https://jenkins.werfen.com/job/Werfen%20websites/job/Production%20environment/job/QA%20Transports/job/Werfen%20MX%20hotfix/buildWithParameters?token=WerfenMXHotfix&token2= | I34: =_xlfn.CONCAT("https://jenkins.werfen.com/",D34,"?token=",C34) -> https://jenkins.werfen.com/job/Werfen%20websites/job/Production%20environment/job/QA%20Transports/job/Werfen%20MX%20hotfix/?token=WerfenMXHotfix | J34: 1
A35: Webs | B35: =CONCATENATE($I$4," ",I35,CHAR(10),CHAR(13),CHAR(10),CHAR(13),$H$4," ",H35) -> JENKINS_RESULT https://jenkins.werfen.com/job/Werfen%20websites/job/Production%20environment/job/QA%20Transports/job/Werfen%20ES/?token=WerfenESRelease _x000D_ _x000D_JENKINS_TRANSPORT https://jenkins.werfen.com/job/Werfen%20websites/job/Production%20environment/job/QA%20Transports/job/Werfen%20ES/buildWithParameters?token=WerfenESRelease&token2= | C35: WerfenESRelease | D35: job/Werfen%20websites/job/Production%20environment/job/QA%20Transports/job/Werfen%20ES/ | E35: buildWithParameters | F35: 23 | G35: Website Spain legacy | H35: =CONCATENATE("https://jenkins.werfen.com/",D35,E35,"?token=",C35,"&token2=") -> https://jenkins.werfen.com/job/Werfen%20websites/job/Production%20environment/job/QA%20Transports/job/Werfen%20ES/buildWithParameters?token=WerfenESRelease&token2= | I35: =_xlfn.CONCAT("https://jenkins.werfen.com/",D35,"?token=",C35) -> https://jenkins.werfen.com/job/Werfen%20websites/job/Production%20environment/job/QA%20Transports/job/Werfen%20ES/?token=WerfenESRelease | J35: 0
A36: Webs | B36: =CONCATENATE($I$4," ",I36,CHAR(10),CHAR(13),CHAR(10),CHAR(13),$H$4," ",H36) -> JENKINS_RESULT https://jenkins.werfen.com/job/Werfen%20websites/job/Production%20environment/job/QA%20Transports/job/Werfen%20ES%20release/?token=WerfenESRelease1 _x000D_ _x000D_JENKINS_TRANSPORT https://jenkins.werfen.com/job/Werfen%20websites/job/Production%20environment/job/QA%20Transports/job/Werfen%20ES%20release/buildWithParameters?token=WerfenESRelease1&token2= | C36: WerfenESRelease1 | D36: job/Werfen%20websites/job/Production%20environment/job/QA%20Transports/job/Werfen%20ES%20release/ | E36: buildWithParameters | G36: Website Spain release | H36: =CONCATENATE("https://jenkins.werfen.com/",D36,E36,"?token=",C36,"&token2=") -> https://jenkins.werfen.com/job/Werfen%20websites/job/Production%20environment/job/QA%20Transports/job/Werfen%20ES%20release/buildWithParameters?token=WerfenESRelease1&token2= | I36: =_xlfn.CONCAT("https://jenkins.werfen.com/",D36,"?token=",C36) -> https://jenkins.werfen.com/job/Werfen%20websites/job/Production%20environment/job/QA%20Transports/job/Werfen%20ES%20release/?token=WerfenESRelease1 | J36: 1
A37: Webs | B37: =CONCATENATE($I$4," ",I37,CHAR(10),CHAR(13),CHAR(10),CHAR(13),$H$4," ",H37) -> JENKINS_RESULT https://jenkins.werfen.com/job/Werfen%20websites/job/Production%20environment/job/QA%20Transports/job/Werfen%20ES%20hotfix/?token=WerfenESHotfix _x000D_ _x000D_JENKINS_TRANSPORT https://jenkins.werfen.com/job/Werfen%20websites/job/Production%20environment/job/QA%20Transports/job/Werfen%20ES%20hotfix/buildWithParameters?token=WerfenESHotfix&token2= | C37: WerfenESHotfix | D37: job/Werfen%20websites/job/Production%20environment/job/QA%20Transports/job/Werfen%20ES%20hotfix/ | E37: buildWithParameters | G37: Website Spain hotfix | H37: =CONCATENATE("https://jenkins.werfen.com/",D37,E37,"?token=",C37,"&token2=") -> https://jenkins.werfen.com/job/Werfen%20websites/job/Production%20environment/job/QA%20Transports/job/Werfen%20ES%20hotfix/buildWithParameters?token=WerfenESHotfix&token2= | I37: =_xlfn.CONCAT("https://jenkins.werfen.com/",D37,"?token=",C37) -> https://jenkins.werfen.com/job/Werfen%20websites/job/Production%20environment/job/QA%20Transports/job/Werfen%20ES%20hotfix/?token=WerfenESHotfix | J37: 1
A38: Webs | B38: =CONCATENATE($I$4," ",I38,CHAR(10),CHAR(13),CHAR(10),CHAR(13),$H$4," ",H38) -> JENKINS_RESULT https://jenkins.werfen.com/job/Werfen%20websites/job/Production%20environment/job/QA%20Transports/job/Werfen%20Benelux/?token=WerfenBeneluxRelease _x000D_ _x000D_JENKINS_TRANSPORT https://jenkins.werfen.com/job/Werfen%20websites/job/Production%20environment/job/QA%20Transports/job/Werfen%20Benelux/buildWithParameters?token=WerfenBeneluxRelease&token2= | C38: WerfenBeneluxRelease | D38: job/Werfen%20websites/job/Production%20environment/job/QA%20Transports/job/Werfen%20Benelux/ | E38: buildWithParameters | F38: 5 | G38: Website Benelux legacy | H38: =CONCATENATE("https://jenkins.werfen.com/",D38,E38,"?token=",C38,"&token2=") -> https://jenkins.werfen.com/job/Werfen%20websites/job/Production%20environment/job/QA%20Transports/job/Werfen%20Benelux/buildWithParameters?token=WerfenBeneluxRelease&token2= | I38: =_xlfn.CONCAT("https://jenkins.werfen.com/",D38,"?token=",C38) -> https://jenkins.werfen.com/job/Werfen%20websites/job/Production%20environment/job/QA%20Transports/job/Werfen%20Benelux/?token=WerfenBeneluxRelease | J38: 0
A39: Webs | B39: =CONCATENATE($I$4," ",I39,CHAR(10),CHAR(13),CHAR(10),CHAR(13),$H$4," ",H39) -> JENKINS_RESULT https://jenkins.werfen.com/job/Werfen%20websites/job/Production%20environment/job/QA%20Transports/job/Werfen%20Benelux%20release/?token=WerfenBeneluxRelease1 _x000D_ _x000D_JENKINS_TRANSPORT https://jenkins.werfen.com/job/Werfen%20websites/job/Production%20environment/job/QA%20Transports/job/Werfen%20Benelux%20release/buildWithParameters?token=WerfenBeneluxRelease1&token2= | C39: WerfenBeneluxRelease1 | D39: job/Werfen%20websites/job/Production%20environment/job/QA%20Transports/job/Werfen%20Benelux%20release/ | E39: buildWithParameters | G39: Website Benelux release | H39: =CONCATENATE("https://jenkins.werfen.com/",D39,E39,"?token=",C39,"&token2=") -> https://jenkins.werfen.com/job/Werfen%20websites/job/Production%20environment/job/QA%20Transports/job/Werfen%20Benelux%20release/buildWithParameters?token=WerfenBeneluxRelease1&token2= | I39: =_xlfn.CONCAT("https://jenkins.werfen.com/",D39,"?token=",C39) -> https://jenkins.werfen.com/job/Werfen%20websites/job/Production%20environment/job/QA%20Transports/job/Werfen%20Benelux%20release/?token=WerfenBeneluxRelease1 | J39: 1
A40: Webs | B40: =CONCATENATE($I$4," ",I40,CHAR(10),CHAR(13),CHAR(10),CHAR(13),$H$4," ",H40) -> JENKINS_RESULT https://jenkins.werfen.com/job/Werfen%20websites/job/Production%20environment/job/QA%20Transports/job/Werfen%20Benelux%20hotfix/?token=WerfenBeneluxHotfix _x000D_ _x000D_JENKINS_TRANSPORT https://jenkins.werfen.com/job/Werfen%20websites/job/Production%20environment/job/QA%20Transports/job/Werfen%20Benelux%20hotfix/buildWithParameters?token=WerfenBeneluxHotfix&token2= | C40: WerfenBeneluxHotfix | D40: job/Werfen%20websites/job/Production%20environment/job/QA%20Transports/job/Werfen%20Benelux%20hotfix/ | E40: buildWithParameters | G40: Website Benelux hotfix | H40: =CONCATENATE("https://jenkins.werfen.com/",D40,E40,"?token=",C40,"&token2=") -> https://jenkins.werfen.com/job/Werfen%20websites/job/Production%20environment/job/QA%20Transports/job/Werfen%20Benelux%20hotfix/buildWithParameters?token=WerfenBeneluxHotfix&token2= | I40: =_xlfn.CONCAT("https://jenkins.werfen.com/",D40,"?token=",C40) -> https://jenkins.werfen.com/job/Werfen%20websites/job/Production%20environment/job/QA%20Transports/job/Werfen%20Benelux%20hotfix/?token=WerfenBeneluxHotfix | J40: 1
...

Sheet for SAP
A1: Jenkins ID | B1: Description | C1: Transport Job URL | D1: Transport Result URL | E1: API Token | F1: Valid to
A2: =Transports!F5 -> 1 | B2: =Transports!$G5 -> All werfen sites legacy | C2: =CONCATENATE("https://jenkins.werfen.com/",Transports!$D5,Transports!$E5,"?token=",Transports!$C5,"&token2=") -> https://jenkins.werfen.com/job/Werfen%20websites/job/Production%20environment/job/QA%20Transports/job/All%20werfen.com%20sites/build?token=WerfenALLRelease&token2= | D2: =_xlfn.CONCAT("https://jenkins.werfen.com/",Transports!$D5,"?token=",Transports!$C5) -> https://jenkins.werfen.com/job/Werfen%20websites/job/Production%20environment/job/QA%20Transports/job/All%20werfen.com%20sites/?token=WerfenALLRelease | E2: =Transports!$C$2 -> 11670cc89254539b7527b5113a68e6edb6 | F2: =Transports!$D$3 -> 45962
A3: =Transports!F8 -> 8 | B3: =Transports!$G8 -> Website Czechia legacy | C3: =CONCATENATE("https://jenkins.werfen.com/",Transports!$D8,Transports!$E8,"?token=",Transports!$C8,"&token2=") -> https://jenkins.werfen.com/job/Werfen%20websites/job/Production%20environment/job/QA%20Transports/job/Werfen%20CZ/buildWithParameters?token=WerfenCZRelease&token2= | D3: =_xlfn.CONCAT("https://jenkins.werfen.com/",Transports!$D8,"?token=",Transports!$C8) -> https://jenkins.werfen.com/job/Werfen%20websites/job/Production%20environment/job/QA%20Transports/job/Werfen%20CZ/?token=WerfenCZRelease | E3: =Transports!$C$2 -> 11670cc89254539b7527b5113a68e6edb6 | F3: =Transports!$D$3 -> 45962
A4: =Transports!F11 -> 22 | B4: =Transports!$G11 -> Website Russia legacy | C4: =CONCATENATE("https://jenkins.werfen.com/",Transports!$D11,Transports!$E11,"?token=",Transports!$C11,"&token2=") -> https://jenkins.werfen.com/job/Werfen%20websites/job/Production%20environment/job/QA%20Transports/job/Werfen%20RU/buildWithParameters?token=WerfenRURelease&token2= | D4: =_xlfn.CONCAT("https://jenkins.werfen.com/",Transports!$D11,"?token=",Transports!$C11) -> https://jenkins.werfen.com/job/Werfen%20websites/job/Production%20environment/job/QA%20Transports/job/Werfen%20RU/?token=WerfenRURelease | E4: =Transports!$C$2 -> 11670cc89254539b7527b5113a68e6edb6 | F4: =Transports!$D$3 -> 45962
A5: =Transports!F14 -> 4 | B5: =Transports!$G14 -> Website AUSTRALIA legacy | C5: =CONCATENATE("https://jenkins.werfen.com/",Transports!$D14,Transports!$E14,"?token=",Transports!$C14,"&token2=") -> https://jenkins.werfen.com/job/Werfen%20websites/job/Production%20environment/job/QA%20Transports/job/Werfen%20AU/buildWithParameters?token=WerfenAURelease&token2= | D5: =_xlfn.CONCAT("https://jenkins.werfen.com/",Transports!$D14,"?token=",Transports!$C14) -> https://jenkins.werfen.com/job/Werfen%20websites/job/Production%20environment/job/QA%20Transports/job/Werfen%20AU/?token=WerfenAURelease | E5: =Transports!$C$2 -> 11670cc89254539b7527b5113a68e6edb6 | F5: =Transports!$D$3 -> 45962
A6: =Transports!F17 -> 28 | B6: =Transports!$G17 -> WeListen legacy | C6: =CONCATENATE("https://jenkins.werfen.com/",Transports!$D17,Transports!$E17,"?token=",Transports!$C17,"&token2=") -> https://jenkins.werfen.com/job/WeListen/job/Production%20environment/job/QA%20Transports/job/Deploy%20site/buildWithParameters?token=welistenRelease&token2= | D6: =_xlfn.CONCAT("https://jenkins.werfen.com/",Transports!$D17,"?token=",Transports!$C17) -> https://jenkins.werfen.com/job/WeListen/job/Production%20environment/job/QA%20Transports/job/Deploy%20site/?token=welistenRelease | E6: =Transports!$C$2 -> 11670cc89254539b7527b5113a68e6edb6 | F6: =Transports!$D$3 -> 45962
A7: =Transports!F20 -> 9 | B7: =Transports!$G20 -> Website FRANCE legacy | C7: =CONCATENATE("https://jenkins.werfen.com/",Transports!$D20,Transports!$E20,"?token=",Transports!$C20,"&token2=") -> https://jenkins.werfen.com/job/Werfen%20websites/job/Production%20environment/job/QA%20Transports/job/Werfen%20FR/buildWithParameters?token=WerfenFRRelease&token2= | D7: =_xlfn.CONCAT("https://jenkins.werfen.com/",Transports!$D20,"?token=",Transports!$C20) -> https://jenkins.werfen.com/job/Werfen%20websites/job/Production%20environment/job/QA%20Transports/job/Werfen%20FR/?token=WerfenFRRelease | E7: =Transports!$C$2 -> 11670cc89254539b7527b5113a68e6edb6 | F7: =Transports!$D$3 -> 45962
A8: =Transports!F24 -> 0 | B8: =Transports!$G24 -> Website Italy release | C8: =CONCATENATE("https://jenkins.werfen.com/",Transports!$D24,Transports!$E24,"?token=",Transports!$C24,"&token2=") -> https://jenkins.werfen.com/job/Werfen%20websites/job/Production%20environment/job/QA%20Transports/job/Werfen%20IT%20release/buildWithParameters?token=WerfenITRelease1&token2= | D8: =_xlfn.CONCAT("https://jenkins.werfen.com/",Transports!$D24,"?token=",Transports!$C24) -> https://jenkins.werfen.com/job/Werfen%20websites/job/Production%20environment/job/QA%20Transports/job/Werfen%20IT%20release/?token=WerfenITRelease1 | E8: =Transports!$C$2 -> 11670cc89254539b7527b5113a68e6edb6 | F8: =Transports!$D$3 -> 45962
A9: =Transports!F26 -> 24 | B9: =Transports!$G26 -> Website UK legacy | C9: =CONCATENATE("https://jenkins.werfen.com/",Transports!$D26,Transports!$E26,"?token=",Transports!$C26,"&token2=") -> https://jenkins.werfen.com/job/Werfen%20websites/job/Production%20environment/job/QA%20Transports/job/Werfen%20UK/buildWithParameters?token=WerfenUKRelease&token2= | D9: =_xlfn.CONCAT("https://jenkins.werfen.com/",Transports!$D26,"?token=",Transports!$C26) -> https://jenkins.werfen.com/job/Werfen%20websites/job/Production%20environment/job/QA%20Transports/job/Werfen%20UK/?token=WerfenUKRelease | E9: =Transports!$C$2 -> 11670cc89254539b7527b5113a68e6edb6 | F9: =Transports!$D$3 -> 45962
A10: =Transports!F29 -> 2 | B10: =Transports!$G29 -> Website Corporate legacy | C10: =CONCATENATE("https://jenkins.werfen.com/",Transports!$D29,Transports!$E29,"?token=",Transports!$C29,"&token2=") -> https://jenkins.werfen.com/job/Werfen%20websites/job/Production%20environment/job/QA%20Transports/job/Werfen%20WW/buildWithParameters?token=WerfenWWRelease&token2= | D10: =_xlfn.CONCAT("https://jenkins.werfen.com/",Transports!$D29,"?token=",Transports!$C29) -> https://jenkins.werfen.com/job/Werfen%20websites/job/Production%20environment/job/QA%20Transports/job/Werfen%20WW/?token=WerfenWWRelease | E10: =Transports!$C$2 -> 11670cc89254539b7527b5113a68e6edb6 | F10: =Transports!$D$3 -> 45962
A11: =Transports!F32 -> 18 | B11: =Transports!$G32 -> Website Mexico legacy | C11: =CONCATENATE("https://jenkins.werfen.com/",Transports!$D32,Transports!$E32,"?token=",Transports!$C32,"&token2=") -> https://jenkins.werfen.com/job/Werfen%20websites/job/Production%20environment/job/QA%20Transports/job/Werfen%20MX/buildWithParameters?token=WerfenMXRelease&token2= | D11: =_xlfn.CONCAT("https://jenkins.werfen.com/",Transports!$D32,"?token=",Transports!$C32) -> https://jenkins.werfen.com/job/Werfen%20websites/job/Production%20environment/job/QA%20Transports/job/Werfen%20MX/?token=WerfenMXRelease | E11: =Transports!$C$2 -> 11670cc89254539b7527b5113a68e6edb6 | F11: =Transports!$D$3 -> 45962
A12: =Transports!F35 -> 23 | B12: =Transports!$G35 -> Website Spain legacy | C12: =CONCATENATE("https://jenkins.werfen.com/",Transports!$D35,Transports!$E35,"?token=",Transports!$C35,"&token2=") -> https://jenkins.werfen.com/job/Werfen%20websites/job/Production%20environment/job/QA%20Transports/job/Werfen%20ES/buildWithParameters?token=WerfenESRelease&token2= | D12: =_xlfn.CONCAT("https://jenkins.werfen.com/",Transports!$D35,"?token=",Transports!$C35) -> https://jenkins.werfen.com/job/Werfen%20websites/job/Production%20environment/job/QA%20Transports/job/Werfen%20ES/?token=WerfenESRelease | E12: =Transports!$C$2 -> 11670cc89254539b7527b5113a68e6edb6 | F12: =Transports!$D$3 -> 45962
A13: =Transports!F38 -> 5 | B13: =Transports!$G38 -> Website Benelux legacy | C13: =CONCATENATE("https://jenkins.werfen.com/",Transports!$D38,Transports!$E38,"?token=",Transports!$C38,"&token2=") -> https://jenkins.werfen.com/job/Werfen%20websites/job/Production%20environment/job/QA%20Transports/job/Werfen%20Benelux/buildWithParameters?token=WerfenBeneluxRelease&token2= | D13: =_xlfn.CONCAT("https://jenkins.werfen.com/",Transports!$D38,"?token=",Transports!$C38) -> https://jenkins.werfen.com/job/Werfen%20websites/job/Production%20environment/job/QA%20Transports/job/Werfen%20Benelux/?token=WerfenBeneluxRelease | E13: =Transports!$C$2 -> 11670cc89254539b7527b5113a68e6edb6 | F13: =Transports!$D$3 -> 45962
A14: =Transports!F41 -> 27 | B14: =Transports!$G41 -> SSM web legacy | C14: =CONCATENATE("https://jenkins.werfen.com/",Transports!$D41,Transports!$E41,"?token=",Transports!$C41,"&token2=") -> https://jenkins.werfen.com/job/WeNet/job/Production%20environment/job/QA%20Transports/job/SSM%20website/buildWithParameters?token=wenetSSMweb&token2= | D14: =_xlfn.CONCAT("https://jenkins.werfen.com/",Transports!$D41,"?token=",Transports!$C41) -> https://jenkins.werfen.com/job/WeNet/job/Production%20environment/job/QA%20Transports/job/SSM%20website/?token=wenetSSMweb | E14: =Transports!$C$2 -> 11670cc89254539b7527b5113a68e6edb6 | F14: =Transports!$D$3 -> 45962
A15: =Transports!F42 -> 26 | B15: =Transports!$G42 -> WeNet legacy | C15: =CONCATENATE("https://jenkins.werfen.com/",Transports!$D42,Transports!$E42,"?token=",Transports!$C42,"&token2=") -> https://jenkins.werfen.com/job/WeNet/job/Production%20environment/job/QA%20Transports/job/Deploy%20site/buildWithParameters?token=wenetRelease&token2= | D15: =_xlfn.CONCAT("https://jenkins.werfen.com/",Transports!$D42,"?token=",Transports!$C42) -> https://jenkins.werfen.com/job/WeNet/job/Production%20environment/job/QA%20Transports/job/Deploy%20site/?token=wenetRelease | E15: =Transports!$C$2 -> 11670cc89254539b7527b5113a68e6edb6 | F15: =Transports!$D$3 -> 45962
A16: =Transports!F45 -> 25 | B16: =Transports!$G45 -> Website BI (QlikSense) legacy | C16: =CONCATENATE("https://jenkins.werfen.com/",Transports!$D45,Transports!$E45,"?token=",Transports!$C45,"&token2=") -> https://jenkins.werfen.com/job/Werfen%20websites/job/Production%20environment/job/QA%20Transports/job/QLikSense%20Release/buildWithParameters?token=QlikSenseRelease&token2= | D16: =_xlfn.CONCAT("https://jenkins.werfen.com/",Transports!$D45,"?token=",Transports!$C45) -> https://jenkins.werfen.com/job/Werfen%20websites/job/Production%20environment/job/QA%20Transports/job/QLikSense%20Release/?token=QlikSenseRelease | E16: =Transports!$C$2 -> 11670cc89254539b7527b5113a68e6edb6 | F16: =Transports!$D$3 -> 45962
A17: =Transports!F48 -> 10 | B17: =Transports!$G48 -> Website Germany legacy | C17: =CONCATENATE("https://jenkins.werfen.com/",Transports!$D48,Transports!$E48,"?token=",Transports!$C48,"&token2=") -> https://jenkins.werfen.com/job/Werfen%20websites/job/Production%20environment/job/QA%20Transports/job/Werfen%20DE/buildWithParameters?token=WerfenDERelease&token2= | D17: =_xlfn.CONCAT("https://jenkins.werfen.com/",Transports!$D48,"?token=",Transports!$C48) -> https://jenkins.werfen.com/job/Werfen%20websites/job/Production%20environment/job/QA%20Transports/job/Werfen%20DE/?token=WerfenDERelease | E17: =Transports!$C$2 -> 11670cc89254539b7527b5113a68e6edb6 | F17: =Transports!$D$3 -> 45962
A18: =Transports!F51 -> 6 | B18: =Transports!$G51 -> Website Brazil legacy | C18: =CONCATENATE("https://jenkins.werfen.com/",Transports!$D51,Transports!$E51,"?token=",Transports!$C51,"&token2=") -> https://jenkins.werfen.com/job/Werfen%20websites/job/Production%20environment/job/QA%20Transports/job/Werfen%20BR/buildWithParameters?token=WerfenBRRelease&token2= | D18: =_xlfn.CONCAT("https://jenkins.werfen.com/",Transports!$D51,"?token=",Transports!$C51) -> https://jenkins.werfen.com/job/Werfen%20websites/job/Production%20environment/job/QA%20Transports/job/Werfen%20BR/?token=WerfenBRRelease | E18: =Transports!$C$2 -> 11670cc89254539b7527b5113a68e6edb6 | F18: =Transports!$D$3 -> 45962
A19: =Transports!F54 -> 16 | B19: =Transports!$G54 -> Website Leventon legacy | C19: =CONCATENATE("https://jenkins.werfen.com/",Transports!$D54,Transports!$E54,"?token=",Transports!$C54,"&token2=") -> https://jenkins.werfen.com/job/Werfen%20websites/job/Production%20environment/job/QA%20Transports/job/Leventon/buildWithParameters?token=LeventonRelease&token2= | D19: =_xlfn.CONCAT("https://jenkins.werfen.com/",Transports!$D54,"?token=",Transports!$C54) -> https://jenkins.werfen.com/job/Werfen%20websites/job/Production%20environment/job/QA%20Transports/job/Leventon/?token=LeventonRelease | E19: =Transports!$C$2 -> 11670cc89254539b7527b5113a68e6edb6 | F19: =Transports!$D$3 -> 45962
A20: =Transports!F59 -> 0 | B20: =Transports!$G59 -> Website Portugal hotfix | C20: =CONCATENATE("https://jenkins.werfen.com/",Transports!$D59,Transports!$E59,"?token=",Transports!$C59,"&token2=") -> https://jenkins.werfen.com/job/Werfen%20websites/job/Production%20environment/job/QA%20Transports/job/Werfen%20PT%20hotfix/buildWithParameters?token=WerfenPTHotifx&token2= | D20: =_xlfn.CONCAT("https://jenkins.werfen.com/",Transports!$D59,"?token=",Transports!$C59) -> https://jenkins.werfen.com/job/Werfen%20websites/job/Production%20environment/job/QA%20Transports/job/Werfen%20PT%20hotfix/?token=WerfenPTHotifx | E20: =Transports!$C$2 -> 11670cc89254539b7527b5113a68e6edb6 | F20: =Transports!$D$3 -> 45962
A21: =Transports!F60 -> 15 | B21: =Transports!$G60 -> Website Korea legacy | C21: =CONCATENATE("https://jenkins.werfen.com/",Transports!$D60,Transports!$E60,"?token=",Transports!$C60,"&token2=") -> https://jenkins.werfen.com/job/Werfen%20websites/job/Production%20environment/job/QA%20Transports/job/Werfen%20KR/buildWithParameters?token=WerfenKRRelease&token2= | D21: =_xlfn.CONCAT("https://jenkins.werfen.com/",Transports!$D60,"?token=",Transports!$C60) -> https://jenkins.werfen.com/job/Werfen%20websites/job/Production%20environment/job/QA%20Transports/job/Werfen%20KR/?token=WerfenKRRelease | E21: =Transports!$C$2 -> 11670cc89254539b7527b5113a68e6edb6 | F21: =Transports!$D$3 -> 45962
A22: =Transports!F63 -> 14 | B22: =Transports!$G63 -> Website Japan legacy | C22: =CONCATENATE("https://jenkins.werfen.com/",Transports!$D63,Transports!$E63,"?token=",Transports!$C63,"&token2=") -> https://jenkins.werfen.com/job/Werfen%20websites/job/Production%20environment/job/QA%20Transports/job/Werfen%20JP/buildWithParameters?token=WerfenJPRelease&token2= | D22: =_xlfn.CONCAT("https://jenkins.werfen.com/",Transports!$D63,"?token=",Transports!$C63) -> https://jenkins.werfen.com/job/Werfen%20websites/job/Production%20environment/job/QA%20Transports/job/Werfen%20JP/?token=WerfenJPRelease | E22: =Transports!$C$2 -> 11670cc89254539b7527b5113a68e6edb6 | F22: =Transports!$D$3 -> 45962
A23: =Transports!F66 -> 7 | B23: =Transports!$G66 -> Website China AWS legacy | C23: =CONCATENATE("https://jenkins.werfen.com/",Transports!$D66,Transports!$E66,"?token=",Transports!$C66,"&token2=") -> https://jenkins.werfen.com/job/Werfen%20websites/job/Production%20environment/job/QA%20Transports/job/Werfen%20CN%20-%20AWS/build?token=WerfenCNRelease&token2= | D23: =_xlfn.CONCAT("https://jenkins.werfen.com/",Transports!$D66,"?token=",Transports!$C66) -> https://jenkins.werfen.com/job/Werfen%20websites/job/Production%20environment/job/QA%20Transports/job/Werfen%20CN%20-%20AWS/?token=WerfenCNRelease | E23: =Transports!$C$2 -> 11670cc89254539b7527b5113a68e6edb6 | F23: =Transports!$D$3 -> 45962
A24: =Transports!F69 -> 20 | B24: =Transports!$G69 -> Website OEM legacy | C24: =CONCATENATE("https://jenkins.werfen.com/",Transports!$D69,Transports!$E69,"?token=",Transports!$C69,"&token2=") -> https://jenkins.werfen.com/job/Werfen%20websites/job/Production%20environment/job/QA%20Transports/job/Werfen%20OEM/buildWithParameters?token=WerfenOEMRelease&token2= | D24: =_xlfn.CONCAT("https://jenkins.werfen.com/",Transports!$D69,"?token=",Transports!$C69) -> https://jenkins.werfen.com/job/Werfen%20websites/job/Production%20environment/job/QA%20Transports/job/Werfen%20OEM/?token=WerfenOEMRelease | E24: =Transports!$C$2 -> 11670cc89254539b7527b5113a68e6edb6 | F24: =Transports!$D$3 -> 45962
A25: =Transports!F72 -> 19 | B25: =Transports!$G72 -> Website NoAm legacy | C25: =CONCATENATE("https://jenkins.werfen.com/",Transports!$D72,Transports!$E72,"?token=",Transports!$C72,"&token2=") -> https://jenkins.werfen.com/job/Werfen%20websites/job/Production%20environment/job/QA%20Transports/job/Werfen%20NoAm/buildWithParameters?token=WerfenNoAmRelease&token2= | D25: =_xlfn.CONCAT("https://jenkins.werfen.com/",Transports!$D72,"?token=",Transports!$C72) -> https://jenkins.werfen.com/job/Werfen%20websites/job/Production%20environment/job/QA%20Transports/job/Werfen%20NoAm/?token=WerfenNoAmRelease | E25: =Transports!$C$2 -> 11670cc89254539b7527b5113a68e6edb6 | F25: =Transports!$D$3 -> 45962
A26: =Transports!F75 -> 3 | B26: =Transports!$G75 -> Website Austria legacy | C26: =CONCATENATE("https://jenkins.werfen.com/",Transports!$D75,Transports!$E75,"?token=",Transports!$C75,"&token2=") -> https://jenkins.werfen.com/job/Werfen%20websites/job/Production%20environment/job/QA%20Transports/job/Werfen%20AT/buildWithParameters?token=WerfenATRelease&token2= | D26: =_xlfn.CONCAT("https://jenkins.werfen.com/",Transports!$D75,"?token=",Transports!$C75) -> https://jenkins.werfen.com/job/Werfen%20websites/job/Production%20environment/job/QA%20Transports/job/Werfen%20AT/?token=WerfenATRelease | E26: =Transports!$C$2 -> 11670cc89254539b7527b5113a68e6edb6 | F26: =Transports!$D$3 -> 45962
A27: =Transports!F76 -> 30 | B27: =Transports!$G76 -> TicketLine legacy | C27: =CONCATENATE("https://jenkins.werfen.com/",Transports!$D76,Transports!$E76,"?token=",Transports!$C76,"&token2=") -> https://jenkins.werfen.com/job/TicketLine/job/Production%20Environment/job/QA%20Transports/job/TicketLine/buildWithParameters?token=TicketLineRelease&token2= | D27: =_xlfn.CONCAT("https://jenkins.werfen.com/",Transports!$D76,"?token=",Transports!$C76) -> https://jenkins.werfen.com/job/TicketLine/job/Production%20Environment/job/QA%20Transports/job/TicketLine/?token=TicketLineRelease | E27: =Transports!$C$2 -> 11670cc89254539b7527b5113a68e6edb6 | F27: =Transports!$D$3 -> 45962
A28: =Transports!F81 -> 42 | B28: =Transports!$G81 -> Solr Middleware legacy | C28: =CONCATENATE("https://jenkins.werfen.com/",Transports!$D81,Transports!$E81,"?token=",Transports!$C81,"&token2=") -> https://jenkins.werfen.com/job/TicketLine/job/Production%20Environment/job/QA%20Transports/job/Solr%20Middleware/build?token=SolrMiddlewareRelease&token2= | D28: =_xlfn.CONCAT("https://jenkins.werfen.com/",Transports!$D81,"?token=",Transports!$C81) -> https://jenkins.werfen.com/job/TicketLine/job/Production%20Environment/job/QA%20Transports/job/Solr%20Middleware/?token=SolrMiddlewareRelease | E28: =Transports!$C$2 -> 11670cc89254539b7527b5113a68e6edb6 | F28: =Transports!$D$3 -> 45962
